Workbook
Name ACTION: #REF!

Sheet Test Report
A1: TEST REPORT
B2: version: | C2: 4
B3: Note: | C3: done
B4: Date | C4: 46059
B7: No | C7: Module code | D7: Pass | E7: Fail | F7: Pending | G7: Number of test cases
B8: 1 | C8: CR101 - Chức năng Quản lý Sản phẩm | D8: =COUNTIF('Chức năng Quản lý Sản phẩm '!I:I,"Pass") -> 60 | E8: =COUNTIF('Chức năng Quản lý Sản phẩm '!I:I,"Fail") -> 58 | F8: =COUNTIF('Chức năng Quản lý Sản phẩm '!I:I,"Pending") -> 0 | G8: =SUM(D8:F8) -> 118
B9: 2 | C9: CR102 - Chức năng Giỏ hàng | D9: =COUNTIF('Chức năng giỏ hàng'!I:I,"Pass") -> 67 | E9: =COUNTIF('Chức năng giỏ hàng'!I:I,"Fail") -> 13 | F9: =COUNTIF('Chức năng giỏ hàng'!I:I,"Pending") -> 0 | G9: =SUM(D9:F9) -> 80
B10: 3 | C10: CR103 - Chức năng Quản lý tài khoản | D10: =COUNTIF('Chức năng Quản lý tài khoản'!I:I,"Pass") -> 44 | E10: =COUNTIF('Chức năng Quản lý tài khoản'!I:I,"Fail") -> 23 | F10: =COUNTIF('Chức năng Quản lý tài khoản'!I:I,"Pending") -> 3 | G10: =SUM(D10:F10) -> 70
B11: 4 | C11: CR104 | D11: =COUNTIF('Chức năng thanh toán'!G:G,"Pass") -> 47 | E11: =COUNTIF('Chức năng thanh toán'!G:G,"Fail") -> 23 | F11: =COUNTIF('Chức năng thanh toán'!G:G,"Pending") -> 0 | G11: =SUM(D11:F11) -> 70
B12: 5 | C12: CR105 -chức năng Báo cáo thống kê | D12: =COUNTIF('chức năng Báo cáo thống kê'!I:I,"Pass") -> 43 | E12: =COUNTIF('chức năng Báo cáo thống kê'!I:I,"Fail") -> 37 | F12: =COUNTIF('chức năng Báo cáo thống kê'!I:I,"Pending") -> 0 | G12: =COUNTIF('chức năng Báo cáo thống kê'!I:I,"Pass")+COUNTIF('chức năng Báo cáo thống kê'!I:I,"Fail") -> 80
C13: Sub total | D13: =SUM(D8:D12) -> 261 | E13: =SUM(E8:E12) -> 154 | F13: =SUM(F8:F12) -> 3 | G13: =SUM(G8:G12) -> 418
C15: Test coverage | E15: =(D13+E13)*100/G13 -> 99.282297 | F15: %
C16: Test successful coverage | E16: =D13*100/G13 -> 62.440191 | F16: %

Sheet chức năng Báo cáo thống kê
A1: TEST CASE
A3: System Name： | B3: Nupakachi Shop - Online Shopping Website
A4: Module Code： | B4: CR500 - Reporting & System Reliability
A5: Test requirement: | B5: CR5 - Báo cáo doanh thu, báo cáo thống kê, Reliability, Performance, Endurance
A6: Pass | B6: =COUNTIF(I12:I98,"Pass") -> 43 | C6: Pending | D6: =COUNTIF(I12:I86,"Pending") -> 0 | H6: By: Nguyễn Thị Thùy Dương
A7: Fail | B7: =COUNTIF(I12:I98,"Fail") -> 37 | C7: Number of test cases: | D7: =COUNTIF(A12:A98,"*TC*") -> 80
A9: ID | B9: Test Case Description | C9: Test Case Procedure | D9: Expected Output | H9: Test date | I9: Result | J9: Note | K9: BUG ID | L9: Tester
A11: 1. UNIT TEST CASES - RevenueService / StatisticsService / ReportService
A12: TC01 | B12: Unit Test - Tính tổng doanh thu hợp lệ | C12: 1. Chuẩn bị dữ liệu kiểm thử_ danh sách đơn hàng đã thanh toán 2.Thực thi gọi RevenueService.CalculateTotalRevenue(). 3.trả về tổng doanh thu . | D12: Tổng doanh thu bằng tổng tiền của các đơn hàng đã thanh toán. | H12: =DATEVALUE("05/19/2026") -> 46161 | I12: Pass | L12: Nguyễn Thị Thùy Dương
A13: TC02 | B13: Unit Test - Không tính đơn hàng đã hủy | C13: 1.chuẩn bị danh sách gồm đơn đã thanh toán và đơn đã hủy. 2. gọi hàm tính tổng doanh thu. 3. trả về kết quả. | D13: Doanh thu chỉ tính đơn đã thanh toán, bỏ qua đơn đã hủy. | H13: =DATEVALUE("05/19/2026") -> 46161 | I13: Pass | L13: Nguyễn Thị Thùy Dương
A14: TC03 | B14: Unit Test - Doanh thu khi không có dữ liệu | C14: 1. chuẩn bị danh sách đơn hàng rỗng. 2. thực hiện gọi hàm tính doanh thu. 3.trả về kết quả. | D14: Hệ thống trả về 0, không phát sinh exception. | H14: =DATEVALUE("05/19/2026") -> 46161 | I14: Pass | L14: Nguyễn Thị Thùy Dương
A15: TC04 | B15: Unit Test - Validate khoảng ngày hợp lệ | C15: 1. chọn FromDate nhỏ hơn hoặc bằng ToDate. 2. gọi ReportService.ValidateDateRange(). 3. kết quả. | D15: Validate trả về true hoặc không có lỗi. | H15: =DATEVALUE("05/19/2026") -> 46161 | I15: Pass | L15: Nguyễn Thị Thùy Dương
A16: TC05 | B16: Unit Test - Validate ngày bắt đầu lớn hơn ngày kết thúc | C16: 1. chọn FromDate > ToDate. 2. gọi ValidateDateRange(). 3. kết quả trả về. | D16: Hệ thống trả về lỗi ngày bắt đầu không được lớn hơn ngày kết thúc. | H16: =DATEVALUE("05/19/2026") -> 46161 | I16: Pass | L16: Nguyễn Thị Thùy Dương
A17: TC06 | B17: Unit Test - Validate ngày tương lai | C17: 1. chọn ToDate lớn hơn ngày hiện tại. 2. gọi ValidateDateRange(). 3. kết quả trả về. | D17: Hệ thống trả về lỗi không cho chọn ngày sau ngày hiện tại. | H17: =DATEVALUE("05/19/2026") -> 46161 | I17: Pass | L17: Nguyễn Thị Thùy Dương
A18: TC07 | B18: Unit Test - Đếm số đơn hàng | C18: 1. chuẩn bị danh sách đơn hàng theo trạng thái. 2. gọi StatisticsService.CountOrders(). 3. số lượng. | D18: Số đơn hàng trả về đúng theo dữ liệu đầu vào. | H18: =DATEVALUE("05/19/2026") -> 46161 | I18: Pass | L18: Nguyễn Thị Thùy Dương
A19: TC08 | B19: Unit Test - Đếm đơn hàng theo trạng thái | C19: 1. danh sách đơn hàng: Chờ xác nhận, Đã giao, Đã hủy. 2. gọi CountOrdersByStatus(). 3. kết quả từng nhóm. | D19: Số đơn theo từng trạng thái chính xác. | H19: =DATEVALUE("05/19/2026") -> 46161 | I19: Pass | L19: Nguyễn Thị Thùy Dương
A20: TC09 | B20: Unit Test - Lấy top sản phẩm bán chạy | C20: 1. danh sách chi tiết đơn hàng có số lượng bán. 2. gọi GetTopSellingProducts(). 3. kết quả thứ tự. | D20: Sản phẩm bán nhiều nhất đứng đầu danh sách. | H20: =DATEVALUE("05/19/2026") -> 46161 | I20: Pass | L20: Nguyễn Thị Thùy Dương
A21: TC10 | B21: Unit Test - Top sản phẩm khi trùng số lượng bán | C21: 1.danh sách 2 sản phẩm có cùng số lượng bán. 2. lấy top sản phẩm. 3. kết quả. | D21: Hệ thống vẫn trả về danh sách hợp lệ, không lỗi sắp xếp. | H21: =DATEVALUE("05/19/2026") -> 46161 | I21: Pass | L21: Nguyễn Thị Thùy Dương
A22: TC11 | B22: Unit Test - Thống kê tồn kho hợp lệ | C22: 1. danh sách sản phẩm có SOLUONGTON. 2. gọi GetInventoryStatistics(). 3. kết quả. | D22: Số lượng tồn kho hiển thị đúng, không có số âm. | H22: =DATEVALUE("05/19/2026") -> 46161 | I22: Pass | L22: Nguyễn Thị Thùy Dương
A23: TC12 | B23: Unit Test - Tồn kho âm không hợp lệ | C23: 1. sản phẩm có SOLUONGTON = -1. 2. gọi validate tồn kho. 3. kết quả. | D23: Hệ thống trả về lỗi số lượng tồn kho phải >= 0. | H23: =DATEVALUE("05/19/2026") -> 46161 | I23: Pass | L23: Nguyễn Thị Thùy Dương
... A26: TC15 | B26: Unit Test - Xuất báo cáo không có dữ liệu | C26: 1. danh sách báo cáo rỗng. 2. gọi ReportService.ExportReport(). 3. file/kết quả. | D26: Hệ thống trả về file rỗng có header hoặc thông báo không có dữ liệu, không lỗi. | H26: =DATEVALUE("05/19/2026") -> 46161 | I26: Pass | L26: Nguyễn Thị Thùy Dương
A27: 2. POSTMAN API TEST CASES - Report APIs
A28: TC16 | B28: API - Lấy báo cáo doanh thu hợp lệ | C28: 1. Gửi GET /api/reports/revenue với fromDate/toDate hợp lệ. 2. Kiểm tra status code. 3. Kiểm tra body response. | D28: Status 200, trả về tổng doanh thu và danh sách dữ liệu đúng định dạng JSON. | H28: =DATEVALUE("05/19/2026") -> 46161 | I28: Fail | J28: API /api/ chưa tồn tại hoặc chưa được deploy. Hiện hệ thống chỉ có trang web /Admin/BaocaoThongKe. | K28: BUG1_BaoCaovaThongKe | L28: Nguyễn Thị Thùy Dương
A29: TC17 | B29: API - Revenue thiếu fromDate | C29: 1. Gửi GET /api/reports/revenue chỉ có toDate. 2. Kiểm tra status và message. | D29: Status 400, thông báo thiếu tham số fromDate. | H29: =DATEVALUE("05/19/2026") -> 46161 | I29: Fail | J29: API /api/ chưa tồn tại hoặc chưa được deploy. Hiện hệ thống chỉ có trang web /Admin/BaocaoThongKe. | K29: BUG2_BaoCaovaThongKe | L29: Nguyễn Thị Thùy Dương
A30: TC18 | B30: API - Revenue ngày không hợp lệ | C30: 1. Gửi fromDate = 2026-05-30, toDate = 2026-05-01. 2. Kiểm tra response. | D30: Status 400, báo lỗi ngày bắt đầu không được lớn hơn ngày kết thúc. | H30: =DATEVALUE("05/19/2026") -> 46161 | I30: Fail | J30: Không thể validate fromDate > toDate nếu endpoint không tồn tại | K30: BUG3_BaoCaovaThongKe | L30: Nguyễn Thị Thùy Dương
A31: TC19 | B31: API - Revenue ngày tương lai | C31: 1. Gửi toDate lớn hơn ngày hiện tại. 2. Kiểm tra response. | D31: Status 400, báo lỗi không được chọn ngày sau ngày hiện tại. | H31: =DATEVALUE("05/19/2026") -> 46161 | I31: Fail | J31: Không thể validate ngày tương lai nếu endpoint không tồn tại | K31: BUG4_BaoCaovaThongKe | L31: Nguyễn Thị Thùy Dương
A32: TC20 | B32: API - Revenue không có token | C32: 1. Gửi request không có Authorization header. 2. Kiểm tra status. | D32: Status 401 Unauthorized. | H32: =DATEVALUE("05/19/2026") -> 46161 | I32: Fail | J32: Không thể test auth/token trên revenue API nếu endpoint không tồn tại | K32: BUG5_BaoCaovaThongKe | L32: Nguyễn Thị Thùy Dương
A33: TC21 | B33: API - Revenue token sai | C33: 1. Gửi Authorization: Bearer invalid_token. 2. Kiểm tra status. | D33: Status 401 Unauthorized hoặc 403 Forbidden. | H33: =DATEVALUE("05/19/2026") -> 46161 | I33: Fail | J33: Không thể test token sai nếu revenue API không tồn tại | K33: BUG6_BaoCaovaThongKe | L33: Nguyễn Thị Thùy Dương
A34: TC22 | B34: API - Lấy thống kê đơn hàng | C34: 1. Gửi GET /api/reports/orders với token hợp lệ. 2. Kiểm tra dữ liệu thống kê. | D34: Status 200, trả về số đơn theo trạng thái chính xác. | H34: =DATEVALUE("05/19/2026") -> 46161 | I34: Fail | J34: Đang gọi sai loại endpoint hoặc API /api/reports/top-products chưa tồn tại/chưa được deploy. | K34: BUG7_BaoCaovaThongKe | L34: Nguyễn Thị Thùy Dương
A35: TC23 | B35: API - Orders không có dữ liệu | C35: 1. Gửi request với khoảng ngày không có đơn hàng. 2. Kiểm tra response. | D35: Status 200, data là mảng rỗng hoặc tổng đơn = 0. | H35: =DATEVALUE("05/19/2026") -> 46161 | I35: Fail | J35: Trang hiển thị trạng thái không có dữ liệu | K35: BUG8_BaoCaovaThongKe | L35: Nguyễn Thị Thùy Dương
A36: TC24 | B36: API - Lấy sản phẩm bán chạy | C36: 1. Gửi GET /api/reports/top-products. 2. Kiểm tra thứ tự sản phẩm. | D36: Status 200, sản phẩm được sắp xếp giảm dần theo số lượng bán. | H36: =DATEVALUE("05/19/2026") -> 46161 | I36: Fail | J36: Đang gọi sai loại endpoint hoặc API /api/reports/top-products chưa tồn tại/chưa được deploy. | K36: BUG9_BaoCaovaThongKe | L36: Nguyễn Thị Thùy Dương
A37: TC25 | B37: API - Top products giới hạn top=5 | C37: 1. Gửi GET /api/reports/top-products?top=5. 2. Kiểm tra số lượng item. | D37: Status 200, trả về tối đa 5 sản phẩm. | H37: =DATEVALUE("05/19/2026") -> 46161 | I37: Fail | J37: API endpoint không tồn tại, hệ thống trả về 404 Not Found. | K37: BUG10_BaoCaovaThongKe | L37: Nguyễn Thị Thùy Dương
A38: TC26 | B38: API - Top products top không hợp lệ | C38: 1. Gửi top=-1 hoặc top=abc. 2. Kiểm tra response. | D38: Status 400, báo lỗi tham số top không hợp lệ. | H38: =DATEVALUE("05/19/2026") -> 46161 | I38: Fail | J38: Top products với top không hợp lệ không được xử lý thành công | K38: BUG11_BaoCaovaThongKe | L38: Nguyễn Thị Thùy Dương
A39: TC27 | B39: API - Lấy thống kê tồn kho | C39: 1. Gửi GET /api/reports/inventory. 2. Kiểm tra dữ liệu tồn kho. | D39: Status 200, trả về mã sản phẩm, tên sản phẩm, số lượng tồn. | H39: =DATEVALUE("05/19/2026") -> 46161 | I39: Fail | J39: API /api/ chưa tồn tại hoặc chưa được deploy. Hiện hệ thống chỉ có trang web /Admin/BaocaoThongKe. | K39: BUG12_BaoCaovaThongKe | L39: Nguyễn Thị Thùy Dương
... A42: TC30 | B42: API - Xuất báo cáo PDF | C42: 1. Gửi GET /api/reports/export?type=pdf. 2. Kiểm tra header và file. | D42: Status 200, Content-Type đúng, file PDF tải được. | H42: =DATEVALUE("05/19/2026") -> 46161 | I42: Fail | J42: Phải có chức năng xuất PDF | K42: BUG15_BaoCaovaThongKe | L42: Nguyễn Thị Thùy Dương
A43: 3. SELENIUM UI TEST CASES - Report & Statistics Page
A44: TC31 | B44: Selenium UI - Mở trang báo cáo thống kê | C44: 1. Mở Chrome. 2. Đăng nhập tài khoản Nhân viên/Admin. 3. Click menu Báo cáo thống kê. | D44: Trang Báo cáo thống kê hiển thị, không lỗi trắng trang. | H44: =DATEVALUE("05/31/2026") -> 46173 | I44: Fail | K44: BUG16_BaoCaovaThongKe | L44: Nguyễn Thị Thùy Dương
A45: TC32 | B45: Selenium UI - Hiển thị báo cáo doanh thu theo tháng | C45: 1. Vào trang Báo cáo. 2. Chọn tháng cần xem. 3. Nhấn nút Xem báo cáo. | D45: Bảng và biểu đồ doanh thu theo tháng hiển thị đúng. | H45: =DATEVALUE("05/31/2026") -> 46173 | I45: Fail | K45: BUG17_BaoCaovaThongKe | L45: Nguyễn Thị Thùy Dương
A46: TC33 | B46: Selenium UI - Lọc báo cáo theo ngày hợp lệ | C46: 1. Nhập FromDate và ToDate hợp lệ. 2. Click nút Lọc. 3. Quan sát dữ liệu. | D46: Chỉ hiển thị dữ liệu trong khoảng ngày đã chọn. | H46: =DATEVALUE("05/31/2026") -> 46173 | I46: Fail | K46: BUG18_BaoCaovaThongKe | L46: Nguyễn Thị Thùy Dương
A47: TC34 | B47: Selenium UI - Lọc ngày bắt đầu lớn hơn ngày kết thúc | C47: 1. Nhập FromDate > ToDate. 2. Click Lọc. 3. Kiểm tra thông báo. | D47: Hiển thị lỗi ngày bắt đầu không được lớn hơn ngày kết thúc. | H47: =DATEVALUE("05/31/2026") -> 46173 | I47: Fail | K47: BUG19_BaoCaovaThongKe | L47: Nguyễn Thị Thùy Dương
...

Sheet Chức năng Quản lý Sản phẩm 
A1: TEST CASE
A3: System Name： | B3: Nupakachi Shop - Online Shopping Website
A4: Module Code： | B4: PM01 - Quản lý Sản phẩm
A5: Test requirement: | B5: Thành viên 2 - Quản lý Sản phẩm (Thêm, Sửa, Xóa, Tìm kiếm, Xem)
A6: Pass | B6: =COUNTIF(I13:I152,"Pass") -> 60 | C6: Pending | D6: =COUNTIF(A9:K152,"Pending") -> 0 | J6: By:Lê Thị Tuyết Nhi
A7: Fail | B7: =COUNTIF(I13:I152,"Fail") -> 58 | C7: Number of test cases: | D7: =COUNTIF(I13:I152,"Pass")+COUNTIF(I13:I152,"Fail") -> 118
A9: ID | B9: Test Case Description | C9: Test Case Procedure | D9: Expected Output | H9: Test date | I9: Result | J9: Note | K9: BUG ID | L9: Tester
A11: 1. Thêm sản phẩm (Add Product)
A12: POSTMAN Nguyễn Thị Thùy Dương
A13: TC01 | B13: Thêm sản phẩm với đầy đủ thông tin hợp lệ | C13: 1. Đăng nhập =>Admin. 2. Vào mục Quản lý Sản phẩm => Thêm sản phẩm. 3. Nhập đầy đủ: Tên='Áo thun trắng', Giá=150000, Số lượng tồn=50,Màu sắc='Xanh navi', Kích thước='M', Phân loại='Nữ', Chọn ảnh hợp lệ, Danh mục='Áo thun', Nhà cung cấp='Công ty A', Mô tả='Áo thun cotton 100%'. 4. Nhấn 'Lưu'. | D13: Sản phẩm được tạo thành công, xuất hiện trong danh sách sản phẩm. | H13: 46161 | I13: Pass | L13: Lê Thị Tuyết Nhi
A14: TC02 | B14: Thêm sản phẩm khi bỏ trống tên sản phẩm | C14: 1. Đăng nhập => Admin. 2. Vào Thêm sản phẩm. 3. Để trống trường Tên sản phẩm, điền đầy đủ các trường còn lại. 4. Nhấn 'Lưu'. | D14: Hệ thống hiển thị thông báo lỗi 'Error. An error occurred while processing your request.'. Không lưu sản phẩm. | H14: 46161 | I14: Pass | L14: Lê Thị Tuyết Nhi
A15: TC03 | B15: Thêm sản phẩm khi bỏ trống giá | C15: 1. Đăng nhập => Admin. 2. Vào Thêm sản phẩm. 3. Để trống trường giá của sản phẩm, điền đầy đủ các trường còn lại. 4. Nhấn 'Lưu'. | D15: Hệ thống hiển thị thông báo lỗi 'The GIABAN field is required.'. Không lưu sản phẩm. | H15: 46161 | I15: Pass | L15: Lê Thị Tuyết Nhi
A16: TC04 | B16: Thêm sản phẩm với giá âm | C16: 1. Đăng nhập Admin. 2. Vào Thêm sản phẩm. 3. Nhập Giá = -50000. 4. Nhấn 'Lưu'. | D16: Hệ thống báo lỗi 'Value must be greater than or equal to 0.'. Không lưu sản phẩm. | H16: 46161 | I16: Pass | L16: Lê Thị Tuyết Nhi
A17: TC05 | B17: Thêm sản phẩm với giá = 0 | C17: 1. Đăng nhập Admin. 2. Vào Thêm sản phẩm. 3. Nhập Giá = 0. 4. Nhấn 'Lưu'. | D17: Sản phẩm được tạo thành công, xuất hiện trong danh sách sản phẩm. | H17: 46161 | I17: Pass | L17: Lê Thị Tuyết Nhi
A18: TC06 | B18: Thêm sản phẩm bỏ số lượng tồn | C18: 1. Đăng nhập Admin. 2. Vào Thêm sản phẩm. 3. Bỏ trống Trường số lượng tồn, nhập đầy đủ các thông tin còn lại. 4. Nhấn 'Lưu'. | D18: Hệ thống báo lỗi 'Value must be greater than or equal to 0.'. Không lưu sản phẩm. | H18: 46161 | I18: Pass | L18: Lê Thị Tuyết Nhi
A19: TC07 | B19: Thêm sản phẩm với số lượng tồn âm | C19: 1. Đăng nhập Admin. 2. Vào Thêm sản phẩm. 3. Nhập Số lượng = -10. 4. Nhấn 'Lưu'. | D19: Hệ thống báo lỗi 'Value must be greater than or equal to 0.'. Không lưu sản phẩm. | H19: 46161 | I19: Pass | L19: Lê Thị Tuyết Nhi
A20: TC08 | B20: Thêm sản phẩm với số lượng tồn = 0 | C20: 1. Đăng nhập Admin. 2. Vào Thêm sản phẩm. 3. Nhập Số lượng = 0. 4. Nhấn 'Lưu'. | D20: Sản phẩm được lưu thành công với trạng thái 'Sản phẩm này hiện đã hết hàng'. | H20: 46161 | I20: Pass | L20: Lê Thị Tuyết Nhi
A21: TC09 | B21: Thêm sản phẩm khi bỏ trống màu sắc | C21: 1. Đăng nhập => Admin. 2. Vào Thêm sản phẩm. 3. Để trống trường Màu sắc, điền đầy đủ các trường còn lại. 4. Nhấn 'Lưu'. | D21: Hệ thống hiển thị thông báo lỗi 'Error. An error occurred while processing your request.'. Không lưu sản phẩm. | H21: 46161 | I21: Pass | L21: Lê Thị Tuyết Nhi
A22: TC10 | B22: Thêm sản phẩm khi bỏ trống kích tthước | C22: 1. Đăng nhập => Admin. 2. Vào Thêm sản phẩm. 3. Để trống trường Kích thước, điền đầy đủ các trường còn lại. 4. Nhấn 'Lưu'. | D22: Hệ thống hiển thị thông báo lỗi 'Error. An error occurred while processing your request.'. Không lưu sản phẩm. | H22: 46161 | I22: Pass | L22: Lê Thị Tuyết Nhi
A23: TC11 | B23: Thêm sản phẩm với kích thước là một con số (12) | C23: 1. Đăng nhập => Admin. 2. Vào Thêm sản phẩm. 3. Để trống trường Kích thước=12, điền đầy đủ các trường còn lại. 4. Nhấn 'Lưu'. | D23: Hệ thống hiển thị thông báo lỗi 'Error. An error occurred while processing your request.'. Không lưu sản phẩm. | H23: 46161 | I23: Pass | L23: Lê Thị Tuyết Nhi
A24: TC12 | B24: Thêm sản phẩm khi bỏ trống phân loại | C24: 1. Đăng nhập => Admin. 2. Vào Thêm sản phẩm. 3. Để trống trường Phân loại, điền đầy đủ các trường còn lại. 4. Nhấn 'Lưu'. | D24: Hệ thống hiển thị thông báo lỗi 'Error. An error occurred while processing your request.'. Không lưu sản phẩm. | H24: 46161 | I24: Pass | L24: Lê Thị Tuyết Nhi
... A34: TC22 | B34: Thêm sản phẩm với giá rất lớn (999,999,999) | C34: 1. Đăng nhập Admin. 2. Vào Thêm sản phẩm. 3. Nhập Giá = 999999999. 4. Nhấn 'Lưu'. | D34: Hệ thống báo lỗi 'Please enter the valid are 999999000 and 1000000000.'. Không lưu sản phẩm. | H34: 46170 | I34: Pass | L34: Lê Thị Tuyết Nhi
A35: UNIT TEST Nguyễn Thị Thùy Dương
A36: TC023 | B36: Thêm sản phẩm khi bỏ trống tên sản phẩm | C36: 1. Đăng nhập => Admin. 2. Vào Thêm sản phẩm. 3. Để trống trường Tên sản phẩm, điền đầy đủ các trường còn lại. 4. Nhấn 'Lưu'. | D36: Hệ thống hiển thị thông báo lỗi 'Error. An error occurred while processing your request.'. Không lưu sản phẩm. | H36: 46161 | I36: Pass | L36: Lê Thị Tuyết Nhi
A37: TC024 | B37: Thêm sản phẩm với giá âm | C37: 1. Đăng nhập Admin. 2. Vào Thêm sản phẩm. 3. Nhập Giá = -50000. 4. Nhấn 'Lưu'. | D37: Hệ thống báo lỗi 'Value must be greater than or equal to 0.'. Không lưu sản phẩm. | H37: 46161 | I37: Pass | L37: Lê Thị Tuyết Nhi
A38: TC025 | B38: Thêm sản phẩm với giá = 0 | C38: 1. Đăng nhập Admin. 2. Vào Thêm sản phẩm. 3. Nhập Giá = 0. 4. Nhấn 'Lưu'. | D38: Sản phẩm được tạo thành công, xuất hiện trong danh sách sản phẩm. | H38: 46161 | I38: Pass | L38: Lê Thị Tuyết Nhi
A39: TC026 | B39: Thêm sản phẩm với số lượng tồn âm | C39: 1. Đăng nhập Admin. 2. Vào Thêm sản phẩm. 3. Nhập Số lượng = -10. 4. Nhấn 'Lưu'. | D39: Hệ thống báo lỗi 'Value must be greater than or equal to 0.'. Không lưu sản phẩm. | H39: 46161 | I39: Pass | L39: Lê Thị Tuyết Nhi
A40: TC027 | B40: Thêm sản phẩm với số lượng tồn = 0 | C40: 1. Đăng nhập Admin. 2. Vào Thêm sản phẩm. 3. Nhập Số lượng = 0. 4. Nhấn 'Lưu'. | D40: Sản phẩm được lưu thành công với trạng thái 'Sản phẩm này hiện đã hết hàng'. | H40: 46161 | I40: Pass | L40: Lê Thị Tuyết Nhi
A41: TC028 | B41: Thêm sản phẩm với ảnh sai định dạng (PDF) | C41: 1. Đăng nhập Admin. 2. Vào Thêm sản phẩm. 3. Upload file .pdf làm ảnh sản phẩm. 4. Nhấn 'Lưu'. | D41: Hệ thống báo lỗi 'Error. An error occurred while processing your request.'. Không lưu sản phẩm. | H41: 46161 | I41: Pass | L41: Lê Thị Tuyết Nhi
A42: TC029 | B42: Thêm sản phẩm với giá nhập chữ thay vì số | C42: 1. Đăng nhập Admin. 2. Vào Thêm sản phẩm. 3. Nhập Giá = 'abc'. 4. Nhấn 'Lưu'. | D42: Hệ thống chỉ cho nhập số không cho nhập chữ. | H42: 46161 | I42: Pass | L42: Lê Thị Tuyết Nhi
A43: TC030 | B43: Thêm sản phẩm với giá rất lớn (999,999,999) | C43: 1. Đăng nhập Admin. 2. Vào Thêm sản phẩm. 3. Nhập Giá = 999999999. 4. Nhấn 'Lưu'. | D43: Hệ thống báo lỗi 'Please enter the valid are 999999000 and 1000000000.'. Không lưu sản phẩm. | H43: 46161 | I43: Pass | L43: Lê Thị Tuyết Nhi
A44: SELENIUM
A45: TC31 | B45: Thêm sản phẩm với đầy đủ thông tin hợp lệ | C45: 1. Đăng nhập =>Admin. 2. Vào mục Quản lý Sản phẩm => Thêm sản phẩm. 3. Nhập đầy đủ: Tên='Áo thun trắng', Giá=150000, Số lượng tồn=50,Màu sắc='Xanh navi', Kích thước='M', Phân loại='Nữ', Chọn ảnh hợp lệ, Danh mục='Áo thun', Nhà cung cấp='Công ty A', Mô tả='Áo thun cotton 100%'. 4. Nhấn 'Lưu'. | D45: Sản phẩm được tạo thành công, xuất hiện trong danh sách sản phẩm. | H45: 46161 | I45: Fail | J45: Không thể đăng nhập tài khoản Admin bằng Selenium Test | K45: BUG1_Quản lý sản phẩm | L45: Lê Thị Tuyết Nhi
A46: TC32 | B46: Thêm sản phẩm khi bỏ trống tên sản phẩm | C46: 1. Đăng nhập => Admin. 2. Vào Thêm sản phẩm. 3. Để trống trường Tên sản phẩm, điền đầy đủ các trường còn lại. 4. Nhấn 'Lưu'. | D46: Hệ thống hiển thị thông báo lỗi 'Error. An error occurred while processing your request.'. Không lưu sản phẩm. | H46: 46161 | I46: Fail | J46: Không thể đăng nhập tài khoản Admin bằng Selenium Test | K46: BUG2_Quản lý sản phẩm | L46: Lê Thị Tuyết Nhi
A47: TC33 | B47: Thêm sản phẩm khi bỏ trống giá | C47: 1. Đăng nhập => Admin. 2. Vào Thêm sản phẩm. 3. Để trống trường giá của sản phẩm, điền đầy đủ các trường còn lại. 4. Nhấn 'Lưu'. | D47: Hệ thống hiển thị thông báo lỗi 'The GIABAN field is required.'. Không lưu sản phẩm. | H47: 46161 | I47: Fail | J47: Không thể đăng nhập tài khoản Admin bằng Selenium Test | K47: BUG3_Quản lý sản phẩm | L47: Lê Thị Tuyết Nhi
A48: TC34 | B48: Thêm sản phẩm với giá âm | C48: 1. Đăng nhập Admin. 2. Vào Thêm sản phẩm. 3. Nhập Giá = -50000. 4. Nhấn 'Lưu'. | D48: Hệ thống báo lỗi 'Value must be greater than or equal to 0.'. Không lưu sản phẩm. | H48: 46161 | I48: Fail | J48: Không thể đăng nhập tài khoản Admin bằng Selenium Test | K48: BUG4_Quản lý sản phẩm | L48: Lê Thị Tuyết Nhi
A49: TC35 | B49: Thêm sản phẩm với giá = 0 | C49: 1. Đăng nhập Admin. 2. Vào Thêm sản phẩm. 3. Nhập Giá = 0. 4. Nhấn 'Lưu'. | D49: Sản phẩm được tạo thành công, xuất hiện trong danh sách sản phẩm. | H49: 46161 | I49: Fail | J49: Không thể đăng nhập tài khoản Admin bằng Selenium Test | K49: BUG5_Quản lý sản phẩm | L49: Lê Thị Tuyết Nhi
A50: TC36 | B50: Thêm sản phẩm bỏ số lượng tồn | C50: 1. Đăng nhập Admin. 2. Vào Thêm sản phẩm. 3. Bỏ trống Trường số lượng tồn, nhập đầy đủ các thông tin còn lại. 4. Nhấn 'Lưu'. | D50: Hệ thống báo lỗi 'Value must be greater than or equal to 0.'. Không lưu sản phẩm. | H50: 46161 | I50: Fail | J50: Không thể đăng nhập tài khoản Admin bằng Selenium Test | K50: BUG6_Quản lý sản phẩm | L50: Lê Thị Tuyết Nhi
A51: TC37 | B51: Thêm sản phẩm với số lượng tồn âm | C51: 1. Đăng nhập Admin. 2. Vào Thêm sản phẩm. 3. Nhập Số lượng = -10. 4. Nhấn 'Lưu'. | D51: Hệ thống báo lỗi 'Value must be greater than or equal to 0.'. Không lưu sản phẩm. | H51: 46161 | I51: Fail | J51: Không thể đăng nhập tài khoản Admin bằng Selenium Test | K51: BUG7_Quản lý sản phẩm | L51: Lê Thị Tuyết Nhi
A52: TC38 | B52: Thêm sản phẩm với số lượng tồn = 0 | C52: 1. Đăng nhập Admin. 2. Vào Thêm sản phẩm. 3. Nhập Số lượng = 0. 4. Nhấn 'Lưu'. | D52: Sản phẩm được lưu thành công với trạng thái 'Sản phẩm này hiện đã hết hàng'. | H52: 46161 | I52: Fail | J52: Không thể đăng nhập tài khoản Admin bằng Selenium Test | K52: BUG8_Quản lý sản phẩm | L52: Lê Thị Tuyết Nhi
...

Sheet Chức năng giỏ hàng
A1: TEST CASE
A3: System Name： | B3: Nupakachi Shop - Online Shopping Website
A4: Module Code： | B4: CR200 - Shopping Cart / Gio Hang
A5: Test requirement: | B5: CR6 - Shopping cart validation, automation, performance, reliability, manual UX | E5: By: Hồ Chí Dũng
A6: Pass | B6: =COUNTIF(I12:I96,"Pass") -> 67 | C6: Pending | D6: =COUNTIF(I12:I96,"Pending") -> 0
A7: Fail | B7: =COUNTIF(I12:I96,"Fail") -> 13 | C7: Number of test cases: | D7: =COUNTIF(A12:A96,"*TC*") -> 80
A9: ID | B9: Test Case Description | C9: Test Case Procedure | D9: Expected Output | H9: Test date | I9: Result | J9: Note | K9: BUG ID | L9: Tester
A10: 1. UNIT TEST CASES - CartService / InventoryValidationService / PriceCalculationService
A12: TC01 | B12: Unit Test - Thêm sản phẩm hợp lệ vào giỏ hàng | C12: 1. Khởi tạo CartService. 2. Tạo productId=101, quantity=1, price=250000. 3. Gọi AddItem(). 4. Kiểm tra danh sách giỏ hàng. | D12: Giỏ hàng có 1 item, đúng productId, quantity và price. | H12: =DATEVALUE("05/26/2026") -> 46168 | I12: Pass | J12: CartService.AddItem | L12: Hồ Chí Dũng
A13: TC02 | B13: Unit Test - Thêm sản phẩm đã tồn tại thì cộng dồn số lượng | C13: 1. Giỏ hàng đã có productId=101 quantity=1. 2. Thêm lại productId=101 quantity=2. 3. Kiểm tra quantity sau khi thêm. | D13: Quantity của sản phẩm trong giỏ = 3, không tạo dòng trùng. | H13: =DATEVALUE("05/26/2026") -> 46168 | I13: Pass | J13: CartService.AddItem | L13: Hồ Chí Dũng
A14: TC03 | B14: Unit Test - Xóa sản phẩm khỏi giỏ hàng | C14: 1. Giỏ hàng có productId=101. 2. Gọi RemoveItem(101). 3. Kiểm tra danh sách giỏ hàng. | D14: Sản phẩm bị xóa khỏi giỏ, số item giảm đúng. | H14: =DATEVALUE("05/26/2026") -> 46168 | I14: Pass | J14: CartService.RemoveItem | L14: Hồ Chí Dũng
A15: TC04 | B15: Unit Test - Cập nhật số lượng sản phẩm hợp lệ | C15: 1. Giỏ hàng có productId=101 quantity=1. 2. Gọi UpdateQuantity(101,3). 3. Kiểm tra quantity. | D15: Quantity được cập nhật thành 3. | H15: =DATEVALUE("05/26/2026") -> 46168 | I15: Pass | J15: CartService.UpdateQuantity | L15: Hồ Chí Dũng
A16: TC05 | B16: Unit Test - Không cho cập nhật số lượng bằng 0 | C16: 1. Giỏ hàng có productId=101. 2. Gọi UpdateQuantity(101,0). 3. Kiểm tra exception/message. | D16: Hệ thống trả lỗi hoặc không cho cập nhật quantity = 0. | H16: =DATEVALUE("05/26/2026") -> 46168 | I16: Pass | J16: InventoryValidationService | L16: Hồ Chí Dũng
A17: TC06 | B17: Unit Test - Không cho cập nhật số lượng âm | C17: 1. Giỏ hàng có productId=101. 2. Gọi UpdateQuantity(101,-1). 3. Kiểm tra exception/message. | D17: Hệ thống trả lỗi số lượng không hợp lệ. | H17: =DATEVALUE("05/26/2026") -> 46168 | I17: Pass | J17: InventoryValidationService | L17: Hồ Chí Dũng
A18: TC07 | B18: Unit Test - Không cho số lượng vượt tồn kho | C18: 1. Product stock=5. 2. Gọi AddItem(productId=101, quantity=10). 3. Kiểm tra kết quả validate. | D18: Hệ thống trả lỗi số lượng vượt tồn kho. | H18: =DATEVALUE("05/26/2026") -> 46168 | I18: Pass | J18: InventoryValidationService | L18: Hồ Chí Dũng
A19: TC08 | B19: Unit Test - Tính tổng tiền giỏ hàng | C19: 1. Tạo 2 item: 250000x2 và 150000x1. 2. Gọi CalculateTotal(). 3. So sánh tổng tiền. | D19: Tổng tiền = 650000. | H19: =DATEVALUE("05/26/2026") -> 46168 | I19: Pass | J19: PriceCalculationService.CalculateTotal | L19: Hồ Chí Dũng
A20: TC09 | B20: Unit Test - Tính tổng số lượng sản phẩm | C20: 1. Tạo giỏ hàng có quantity 2,3,1. 2. Gọi CountTotalQuantity(). 3. Kiểm tra kết quả. | D20: Tổng số lượng sản phẩm = 6. | H20: =DATEVALUE("05/26/2026") -> 46168 | I20: Pass | J20: CartService.CountTotalQuantity | L20: Hồ Chí Dũng
A21: TC10 | B21: Unit Test - Giỏ hàng rỗng trả về tổng tiền 0 | C21: 1. Khởi tạo giỏ hàng rỗng. 2. Gọi CalculateTotal(). 3. Kiểm tra kết quả. | D21: Tổng tiền = 0, không phát sinh exception. | H21: =DATEVALUE("05/26/2026") -> 46168 | I21: Pass | J21: PriceCalculationService | L21: Hồ Chí Dũng
A22: TC11 | B22: Unit Test - Xóa sản phẩm cuối cùng làm giỏ hàng rỗng | C22: 1. Giỏ hàng chỉ có 1 sản phẩm. 2. Gọi RemoveItem(). 3. Kiểm tra trạng thái giỏ hàng. | D22: Giỏ hàng rỗng, tổng tiền = 0. | H22: =DATEVALUE("05/26/2026") -> 46168 | I22: Pass | J22: CartService.RemoveItem | L22: Hồ Chí Dũng
A23: TC12 | B23: Unit Test - Không cho thêm sản phẩm hết hàng | C23: 1. Product stock=0. 2. Gọi AddItem(productId=101, quantity=1). 3. Kiểm tra validate. | D23: Hệ thống trả lỗi sản phẩm hết hàng. | H23: =DATEVALUE("05/26/2026") -> 46168 | I23: Pass | J23: InventoryValidationService | L23: Hồ Chí Dũng
... A26: TC15 | B26: Unit Test - Tổng tiền chính xác sau nhiều lần cập nhật | C26: 1. Thêm sản phẩm. 2. Cập nhật quantity nhiều lần. 3. Gọi CalculateTotal(). | D26: Tổng tiền cuối cùng đúng theo quantity mới nhất. | H26: =DATEVALUE("05/26/2026") -> 46168 | I26: Pass | J26: PriceCalculationService | L26: Hồ Chí Dũng
A27: 2. POSTMAN API/MVC TEST CASES - Cart endpoints / MVC routes
A28: TC16 | B28: Postman/MVC - Xem giỏ hàng hợp lệ | C28: 1. Đăng nhập tài khoản hợp lệ. 2. Gửi GET /GioHang hoặc route giỏ hàng thực tế. 3. Kiểm tra status và body response. | D28: Status 200, trang/response giỏ hàng hiển thị danh sách sản phẩm. | H28: =DATEVALUE("05/19/2026") -> 46161 | I28: Pass | J28: Nếu website dùng MVC route, thay endpoint theo Network. | L28: Hồ Chí Dũng
A29: TC17 | B29: Postman/API - Thêm sản phẩm vào giỏ hàng hợp lệ | C29: 1. Gửi POST /api/cart/add hoặc route thực tế. 2. Body có productId=101, quantity=1. 3. Kiểm tra response. | D29: Status 200/302, sản phẩm được thêm vào giỏ. | H29: =DATEVALUE("05/19/2026") -> 46161 | I29: Pass | J29: Endpoint giả định, cần chỉnh theo source/Network. | L29: Hồ Chí Dũng
A30: TC18 | B30: Postman/API - Thiếu productId khi thêm giỏ hàng | C30: 1. Gửi request add cart không có productId. 2. Có quantity=1. 3. Kiểm tra status/message. | D30: Status 400 hoặc trả thông báo thiếu productId. | H30: =DATEVALUE("05/19/2026") -> 46161 | I30: Fail | J30: Lỗi nghiêm trọng. Hệ thống đang thiếu Validate dữ liệu ở tầng Backend. Đề xuất Dev phải bổ sung kiểm tra đầu vào trước khi lưu xuống Database để tránh thất thoát số lượng | K30: BUG1_Chức năng giỏ hàng | L30: Hồ Chí Dũng
A31: TC19 | B31: Postman/API - Quantity không hợp lệ bằng 0 | C31: 1. Gửi request add/update cart với quantity=0. 2. Kiểm tra response. | D31: Status 400 hoặc thông báo số lượng không hợp lệ. | H31: =DATEVALUE("05/19/2026") -> 46161 | I31: Fail | K31: BUG2_Chức năng giỏ hàng | L31: Hồ Chí Dũng
A32: TC20 | B32: Postman/API - Quantity âm | C32: 1. Gửi request với quantity=-1. 2. Kiểm tra response. | D32: Status 400 hoặc hệ thống không cho cập nhật số lượng âm. | H32: =DATEVALUE("05/19/2026") -> 46161 | I32: Fail | K32: BUG3_Chức năng giỏ hàng | L32: Hồ Chí Dũng
A33: TC21 | B33: Postman/API - Quantity vượt tồn kho | C33: 1. Gửi productId hợp lệ, quantity lớn hơn tồn kho. 2. Kiểm tra response. | D33: Status 400 hoặc thông báo vượt tồn kho. | H33: =DATEVALUE("05/19/2026") -> 46161 | I33: Fail | K33: BUG4_Chức năng giỏ hàng | L33: Hồ Chí Dũng
A34: TC22 | B34: Postman/API - Chưa đăng nhập xem giỏ hàng | C34: 1. Xóa cookie/session. 2. Gửi request vào trang giỏ hàng. 3. Kiểm tra redirect/status. | D34: Redirect login hoặc status 401/302 tùy hệ thống. | H34: =DATEVALUE("05/19/2026") -> 46161 | I34: Fail | J34: Lỗi bảo mật. Hệ thống chưa chặn quyền truy cập API. Đề xuất thêm bộ lọc (Authorize Filter / Middleware) vào API giỏ hàng để bắt buộc người dùng phải đăng nhập mới được gọi. | K34: BUG5_Chức năng giỏ hàng | L34: Hồ Chí Dũng
A35: TC23 | B35: Postman/API - Session/token sai hoặc hết hạn | C35: 1. Gửi request với cookie/session không hợp lệ. 2. Kiểm tra status. | D35: Hệ thống không cho truy cập, redirect login hoặc trả 401/403. | H35: =DATEVALUE("05/19/2026") -> 46161 | I35: Fail | K35: BUG6_Chức năng giỏ hàng | L35: Hồ Chí Dũng
A36: TC24 | B36: Postman/API - Giỏ hàng rỗng | C36: 1. Xóa hết sản phẩm trong giỏ. 2. Gửi GET cart. 3. Kiểm tra body. | D36: Response hiển thị giỏ hàng rỗng hoặc tổng tiền = 0. | H36: =DATEVALUE("05/19/2026") -> 46161 | I36: Pass | L36: Hồ Chí Dũng
A37: TC25 | B37: Postman/API - Thêm trùng sản phẩm | C37: 1. Thêm productId=101 vào giỏ. 2. Thêm lại cùng productId. 3. Kiểm tra giỏ hàng. | D37: Không tạo dòng trùng; quantity được cộng dồn. | H37: =DATEVALUE("05/19/2026") -> 46161 | I37: Pass | L37: Hồ Chí Dũng
A38: TC26 | B38: Postman/API - Cập nhật số lượng sản phẩm | C38: 1. Gửi PUT/POST update quantity=3. 2. Kiểm tra response/body. | D38: Quantity cập nhật đúng, tổng tiền thay đổi đúng. | H38: =DATEVALUE("05/19/2026") -> 46161 | I38: Pass | L38: Hồ Chí Dũng
A39: TC27 | B39: Postman/API - Xóa một sản phẩm khỏi giỏ hàng | C39: 1. Gửi DELETE/POST remove productId=101. 2. Kiểm tra giỏ hàng. | D39: Sản phẩm bị xóa khỏi giỏ, tổng tiền cập nhật lại. | H39: =DATEVALUE("05/19/2026") -> 46161 | I39: Pass | L39: Hồ Chí Dũng
A40: TC28 | B40: Postman/API - Xóa toàn bộ giỏ hàng | C40: 1. Gửi DELETE /api/cart/clear hoặc route thực tế. 2. Kiểm tra body giỏ hàng. | D40: Giỏ hàng rỗng, tổng tiền = 0. | H40: =DATEVALUE("05/19/2026") -> 46161 | I40: Pass | L40: Hồ Chí Dũng
A41: TC29 | B41: Postman/API - Kiểm tra tổng tiền giỏ hàng | C41: 1. Giỏ hàng có nhiều sản phẩm. 2. Gửi GET total hoặc mở trang giỏ hàng. 3. So sánh tổng tiền. | D41: Tổng tiền bằng tổng đơn giá x số lượng từng item. | H41: =DATEVALUE("05/19/2026") -> 46161 | I41: Pass | L41: Hồ Chí Dũng
A42: TC30 | B42: Postman/API - Response time giỏ hàng | C42: 1. Gửi request xem giỏ hàng. 2. Đo responseTime trong Postman. | D42: Response time < 3000ms, response body không lỗi. | H42: =DATEVALUE("05/19/2026") -> 46161 | I42: Fail | J42: Server phản hồi chậm. Đề xuất tối ưu lại câu truy vấn (Query) hoặc nâng cấp Server để đảm bảo trải nghiệm khách hàng. | K42: BUG7_Chức năng giỏ hàng | L42: Hồ Chí Dũng
A43: 3. SELENIUM UI TEST CASES - Shopping Cart User Interface
A44: TC31 | B44: Selenium UI - Mở trang giỏ hàng | C44: 1. Mở website. 2. Đăng nhập nếu cần. 3. Click icon giỏ hàng. | D44: Trang giỏ hàng mở thành công, không lỗi layout. | H44: =DATEVALUE("05/29/2026") -> 46171 | I44: Pass | J44: Locator: .cart-icon, /GioHang | L44: Hồ Chí Dũng
A45: TC32 | B45: Selenium UI - Thêm sản phẩm từ trang chi tiết | C45: 1. Mở trang chi tiết sản phẩm. 2. Click Thêm vào giỏ. 3. Kiểm tra thông báo/badge. | D45: Sản phẩm được thêm, badge tăng đúng. | H45: =DATEVALUE("05/29/2026") -> 46171 | I45: Pass | J45: button.add-to-cart, .cart-badge | L45: Hồ Chí Dũng
...

Sheet Chức năng Quản lý tài khoản
A1: TEST CASE
A3: System Name： | B3: Nupakachi Shop - Online Shopping Website
A4: Module Code： | B4: TV1 - Quản lý tài khoản
A5: Test requirement: | B5: Quản lý tài khoản (Đăng ký, Đăng nhập, Đăng xuất)
A6: Pass | B6: =COUNTIF(I12:I96,"Pass") -> 44 | C6: Pending | D6: =COUNTIF(I12:I96,"Pending") -> 3
A7: Fail | B7: =COUNTIF(I12:I96,"Fail") -> 23 | C7: Number of test cases: | D7: =COUNTIF(A12:A96,"*TC*") -> 70 | F7: By:Trần Quốc Trường
A9: ID | B9: Test Case Description | C9: Test Case Procedure | D9: Expected Output | H9: Test date | I9: Result | J9: Note | K9: BUG ID | L9: Tester
A11: 1. Đăng kí tài khoản
A12: TC01 | B12: Đăng ký thành công với dữ liệu hợp lệ | C12: 1. Nhập Tên KH: 'Nguyễn Văn A'. 2. Nhập SĐT: '0901234567'. 3. Nhập Tên đăng nhập: 'user123'. 4. Nhập Mật khẩu: 'Password123!'. 5. Nhập Xác nhận MK: 'Abc@13'. 6. Nhập Email: 'test@gmail.com'. 7. Nhấn 'Đăng ký'. | D12: Đăng ký thành công, hệ thống lưu dữ liệu và chuyển hướng đến trang Đăng nhập. | H12: 46137 | I12: Pass | L12: Trần Quốc Trường
A13: TC02 | B13: Đăng ký bỏ trống 'Tên Khách hàng' | C13: 1. Để trống Tên KH 2. Điền hợp lệ các trường khác. 3. Nhấn 'Đăng ký'. | D13: Hệ thống yêu cầu đăng kí lại từ đầu. Không lưu dữ liệu. | H13: 46137 | I13: Pass | L13: Trần Quốc Trường
A14: TC03 | B14: Đăng ký bỏ trống 'Số điện thoại Khách hàng' | C14: 1. Để trống SĐT 2. Điền hợp lệ các trường khác. 3. Nhấn 'Đăng ký'. | D14: Hệ thống yêu cầu đăng kí lại từ đầu. Không lưu dữ liệu. | H14: 46137 | I14: Pass | L14: Trần Quốc Trường
A15: TC04 | B15: Đăng ký bỏ trống 'Tên đăng nhập' | C15: 1. Để trống Tên đăng nhập 2. Điền hợp lệ các trường khác. 3. Nhấn 'Đăng ký'. | D15: Hệ thống yêu cầu đăng kí lại từ đầu. Không lưu dữ liệu. | H15: 46137 | I15: Pass | L15: Trần Quốc Trường
A16: TC05 | B16: Đăng ký bỏ trống 'Mật khẩu' | C16: 1. Để trống Mật khẩu 2. Điền hợp lệ các trường khác. 3. Nhấn 'Đăng ký'. | D16: Hệ thống yêu cầu đăng kí lại từ đầu. Không lưu dữ liệu. | H16: 46137 | I16: Pass | L16: Trần Quốc Trường
A17: TC06 | B17: Đăng ký bỏ trống 'Xác nhận mật khẩu' | C17: 1. Để trống Xác nhận MK 2. Điền hợp lệ các trường khác. 3. Nhấn 'Đăng ký'. | D17: Hệ thống yêu cầu đăng kí lại từ đầu. Không lưu dữ liệu. | H17: 46137 | I17: Pass | L17: Trần Quốc Trường
A18: TC07 | B18: Đăng ký bỏ trống 'Email' | C18: 1. Để trống Email 2. Điền hợp lệ các trường khác. 3. Nhấn 'Đăng ký'. | D18: Hệ thống yêu cầu đăng kí lại từ đầu. Không lưu dữ liệu. | H18: 46137 | I18: Pass | L18: Trần Quốc Trường
A19: TC08 | B19: Đăng ký bỏ trống toàn bộ form | C19: 1. Để trống tất cả 6 trường. 2. Nhấn 'Đăng ký'. | D19: Hệ thống yêu cầu đăng kí lại từ đầu. Không lưu dữ liệu. | H19: 46137 | I19: Pass | L19: Trần Quốc Trường
A20: TC09 | B20: Nhập 'Tên Khách hàng' chứa chữ số | C20: 1. Nhập Tên KH: 'Nguyễn Văn 123'. 2. Điền hợp lệ các trường khác. 3. Nhấn 'Đăng ký'. | D20: Hệ thống yêu cầu đăng kí lại từ đầu. Không lưu dữ liệu. | H20: 46137 | I20: Pass | L20: Trần Quốc Trường
A21: TC10 | B21: Nhập 'Tên Khách hàng' chứa ký tự đặc biệt | C21: 1. Nhập Tên KH: 'Nguyễn @!'. 2. Điền hợp lệ các trường khác. 3. Nhấn 'Đăng ký'. | D21: Hệ thống yêu cầu đăng kí lại từ đầu. Không lưu dữ liệu. | H21: 46137 | I21: Pass | L21: Trần Quốc Trường
A22: TC11 | B22: Nhập 'Số điện thoại' chứa chữ cái | C22: 1. Nhập SĐT: '0901abc234'. 2. Điền hợp lệ các trường khác. 3. Nhấn 'Đăng ký'. | D22: Hệ thống yêu cầu đăng kí lại từ đầu. Không lưu dữ liệu. | H22: 46137 | I22: Pass | L22: Trần Quốc Trường
A23: TC12 | B23: Nhập 'Số điện thoại' thiếu số (< 10 số) | C23: 1. Nhập SĐT: '090123456'. 2. Điền hợp lệ các trường khác. 3. Nhấn 'Đăng ký'. | D23: Hệ thống yêu cầu đăng kí lại từ đầu. Không lưu dữ liệu. | H23: 46137 | I23: Pass | L23: Trần Quốc Trường
A24: TC13 | B24: Nhập 'Số điện thoại' thừa số (> 10 số) | C24: 1. Nhập SĐT: '09012345678'. 2. Điền hợp lệ các trường khác. 3. Nhấn 'Đăng ký' | D24: Hệ thống yêu cầu đăng kí lại từ đầu. Không lưu dữ liệu. | H24: 46137 | I24: Pass | L24: Trần Quốc Trường
A25: TC14 | B25: Nhập 'Số điện thoại' đã tồn tại | C25: 1. Nhập SĐT đã có trong DB. 2. Điền hợp lệ các trường khác. 3. Nhấn 'Đăng ký'. | D25: Hệ thống yêu cầu đăng kí lại từ đầu. Không lưu dữ liệu. | H25: 46137 | I25: Fail | J25: Hệ thống không xử lý được request | K25: BUG1_Quản lý Tài khoản | L25: Trần Quốc Trường
A26: TC15 | B26: Nhập 'Tên đăng nhập' chứa khoảng trắng | C26: 1. Nhập Tên đăng nhập: 'user name'. 2. Điền hợp lệ các trường khác. 3. Nhấn 'Đăng ký'. | D26: Hệ thống yêu cầu đăng kí lại từ đầu. Không lưu dữ liệu. | H26: 46137 | I26: Pass | L26: Trần Quốc Trường
A27: TC16 | B27: Nhập 'Tên đăng nhập' bằng Tiếng Việt có dấu | C27: 1. Nhập Tên đăng nhập: 'người_dùng'. 2. Điền hợp lệ các trường khác. 3. Nhấn 'Đăng ký'. | D27: Hệ thống yêu cầu đăng kí lại từ đầu. Không lưu dữ liệu. | H27: 46137 | I27: Pass | L27: Trần Quốc Trường
A28: TC17 | B28: Nhập 'Tên đăng nhập' đã tồn tại trong DB | C28: 1. Nhập Tên đăng nhập của tài khoản đã tồn tại. 2. Điền hợp lệ các trường khác. 3. Nhấn 'Đăng ký'. | D28: Hệ thống yêu cầu đăng kí lại từ đầu. Không lưu dữ liệu. | H28: 46137 | I28: Fail | J28: Hệ thống không xử lý được request | K28: BUG2_Quản lý Tài khoản | L28: Trần Quốc Trường
A29: TC18 | B29: Nhập 'Mật khẩu' quá ngắn (< 6 ký tự) | C29: 1. Nhập Mật khẩu: '12345'. 2. Nhập Xác nhận MK: '12345'. 3. Điền hợp lệ các trường khác. 4. Nhấn 'Đăng ký'. | D29: Hệ thống yêu cầu đăng kí lại từ đầu. Không lưu dữ liệu. | H29: 46137 | I29: Pass | L29: Trần Quốc Trường
A30: TC19 | B30: Nhập 'Xác nhận mật khẩu' không khớp | C30: 1. Nhập MK: 'Abc@123'. 2. Nhập Xác nhận MK: 'Abc@124'. 3. Điền hợp lệ các trường khác. 4. Nhấn 'Đăng ký'. | D30: Hệ thống yêu cầu đăng kí lại từ đầu. Không lưu dữ liệu. | H30: 46137 | I30: Pass | L30: Trần Quốc Trường
A31: TC20 | B31: Nhập 'Email' sai định dạng (thiếu @) | C31: 1. Nhập Email: 'nvagmail.com'. 2. Điền hợp lệ các trường khác. 3. Nhấn 'Đăng ký'. | D31: Hệ thống báo lỗi định dạng Email không hợp lệ. | H31: 46137 | I31: Pass | L31: Trần Quốc Trường
A32: TC21 | B32: Nhập 'Email' sai định dạng (thiếu domain) | C32: 1. Nhập Email: 'nva@.com' hoặc 'nva@gmail'. 2. Điền hợp lệ các trường khác. 3. Nhấn 'Đăng ký'. | D32: Hệ thống báo lỗi định dạng Email không hợp lệ. | H32: 46137 | I32: Pass | L32: Trần Quốc Trường
A33: TC22 | B33: Nhập 'Email' đã tồn tại trong hệ thống | C33: 1. Nhập Email đã có trong DB. 2. Điền hợp lệ các trường khác. 3. Nhấn 'Đăng ký'. | D33: Hệ thống báo lỗi. | H33: 46137 | I33: Fail | J33: Hệ thống không xử lý được request | K33: BUG3_Quản lý Tài khoản | L33: Trần Quốc Trường
A34: TC23 | B34: Nhập 'Email' có khoảng trắng thừa ở đầu/cuối | C34: 1. Nhập Email: ' nva@gmail.com '. 2. Điền hợp lệ các trường khác. 3. Nhấn 'Đăng ký'. | D34: Đăng ký thành công, hệ thống tự động loại bỏ khoảng trắng dư thừa. | H34: 46137 | I34: Pass | L34: Trần Quốc Trường
A35: TC24 | B35: Kiểm tra độ dài tối đa của 'Tên Khách hàng' | C35: 1. Nhập Tên KH dài 256 ký tự. 2. Điền hợp lệ các trường khác. 3. Nhấn 'Đăng ký'. | D35: Hệ thống báo lỗi. | H35: 46137 | I35: Pass | L35: Trần Quốc Trường
A36: TC25 | B36: Nhập 'Tên đăng nhập' quá ngắn (< 3 ký tự) | C36: 1. Nhập Tên đăng nhập: 'ab'. 2. Điền hợp lệ các trường khác. 3. Nhấn 'Đăng ký'. | D36: Đăng ký thành công, hệ thống lưu dữ liệu và chuyển hướng đến trang Đăng nhập. | H36: 46137 | I36: Pass | L36: Trần Quốc Trường
A37: TC26 | B37: Submit form bằng phím Enter | C37: 1. Điền đầy đủ thông tin hợp lệ vào 6 trường. 2. Nhấn phím Enter thay vì click chuột. | D37: Đăng ký thành công, hệ thống lưu dữ liệu và chuyển hướng đến trang Đăng nhập. | H37: 46137 | I37: Fail | J37: Lỗi: Form không tự submit khi nhấn phím Enter | K37: BUG4_Quản lý Tài khoản | L37: Trần Quốc Trường
A38: TC27 | B38: Kiểm tra hiển thị ký tự ẩn (Masking) tại ô 'Mật khẩu' và 'Xác nhận mật khẩu' | C38: 1. Click vào ô 'Mật khẩu'. 2. Nhập chuỗi ký tự bất kỳ (VD: 'Abc@123'). 3. Chuyển sang ô 'Xác nhận mật khẩu' và nhập tương tự. 4. Quan sát hiển thị trên màn hình. | D38: Ký tự nhập vào bị ẩn thành dấu chấm (•) hoặc sao (*) để bảo mật, không hiện rõ chữ. | H38: 46137 | I38: Fail | J38: Lỗi bảo mật: Ký tự ô mật khẩu hiển thị ở dạng text thường | K38: BUG5_Quản lý Tài khoản | L38: Trần Quốc Trường
A39: TC28 | B39: Kiểm tra thao tác dán (Paste) dữ liệu vào ô 'Xác nhận mật khẩu' | C39: 1. Nhập mật khẩu hợp lệ vào ô 'Mật khẩu'. 2. Bôi đen và thực hiện lệnh Copy (Ctrl+C). 3. Click chuột vào ô 'Xác nhận mật khẩu' và thực hiện lệnh Dán (Ctrl+V). | D39: Hệ thống chặn thao tác Dán (Paste) để bắt buộc người dùng tự gõ lại xác nhận. | H39: 46137 | I39: Fail | J39: Cảnh báo bảo mật: Giao diện vẫn cho phép dán (paste) mật khẩu | K39: BUG6_Quản lý Tài khoản | L39: Trần Quốc Trường
A40: TC29 | B40: Đăng ký với 'Tên Khách hàng' quá ngắn (1 ký tự) | C40: 1. Nhập Tên KH: 'A'. 2. Nhập thông tin hợp lệ cho 5 trường còn lại. 3. Nhấn nút 'Đăng ký'. | D40: Đăng ký thành công, hệ thống lưu dữ liệu và chuyển hướng đến trang Đăng nhập. | H40: 46137 | I40: Pass | L40: Trần Quốc Trường
A41: TC30 | B41: Đăng ký với 'Tên đăng nhập' trùng lặp nhưng khác biệt về chữ hoa/chữ thường | C41: 1. Giả sử trong cơ sở dữ liệu đã tồn tại Tên đăng nhập là nguyenvana. 2. Điền Tên đăng nhập mới là NGUYENVANA. 3. Điền hợp lệ các trường còn lại. 4. Nhấn nút 'Đăng ký'. | D41: Hệ thống yêu cầu đăng kí lại từ đầu. Không lưu dữ liệu. | H41: 46137 | I41: Pass | L41: Trần Quốc Trường
A42: TC31 | B42: Đăng ký với Email viết hoa | C42: 1. Nhập Email: 'NVA@GMAIL.COM'. 2. Điền hợp lệ các trường khác. 3. Nhấn 'Đăng ký'. | D42: Đăng ký thành công, hệ thống lưu dữ liệu và chuyển hướng đến trang Đăng nhập. | H42: 46137 | I42: Pass | L42: Trần Quốc Trường
A43: TC32 | B43: Kiểm tra 'Số điện thoại' với các đầu số VN | C43: 1. Nhập SĐT hợp lệ (VD: 03x, 09x, 07x). 2. Điền hợp lệ các trường khác. 3. Nhấn 'Đăng ký'. | D43: Đăng ký thành công với tất cả các đầu số nhà mạng Việt Nam. | H43: 46137 | I43: Pass | L43: Trần Quốc Trường
...

Sheet Chức năng thanh toán
A1: TEST CASE
A3: System Name： | B3: Nupakachi Shop - Online Shopping Website
A4: Module Code： | B4: CR500 - Reporting & System Reliability
A5: Test requirement: | B5: CR7_Thanh toán
A6: Pass | B6: =COUNTIF(G12:G96,"Pass") -> 47 | C6: Pending | D6: =COUNTIF(G12:G96,"Pending") -> 0 | F6: By: La Thuận Phát
A7: Fail | B7: =COUNTIF(G12:G96,"Fail") -> 23 | C7: Number of test cases: | D7: =COUNTIF(A12:A96,"*TC*") -> 70
A9: ID | B9: Test Case Description | C9: Test Case Procedure | D9: Expected Output | F9: Test date | G9: Result | H9: Note | I9: BUG ID | J9: Tester
A11: Nhóm UI/UX
A12: TC01 | B12: Trạng thái Loading của nút Đặt hàng | C12: 1. Điền đầy đủ thông tin hợp lệ. 2. Bấm vào btn 'Đặt hàng'. | D12: Nút 'Đặt hàng' bị mờ đi (disable) và hiển thị icon loading vòng tròn. | F12: 46175 | G12: Pass | J12: La Thuận Phát
A13: TC02 | B13: Autofill thông tin tài khoản | C13: 1. Đăng nhập vào tài khoản. 2. Điều hướng vào trang Checkout. | D13: Các field Tên, SĐT, Địa chỉ tự động được điền data đã lưu của user. | F13: 46175 | G13: Pass | J13: La Thuận Phát
A14: TC03 | B14: Bảo lưu form khi thu nhỏ/chuyển tab | C14: 1. Điền data vào form. 2. Chuyển sang tab khác rồi quay lại tab hiện tại. | D14: Dữ liệu đã nhập trên form vẫn được giữ nguyên. | F14: 46175 | G14: Pass | J14: La Thuận Phát
A15: TC04 | B15: Responsive UI trên Mobile/Tablet | C15: 1. Dùng Chrome DevTools mở chế độ Mobile (iPhone/iPad). 2. Kiểm tra hiển thị. | D15: Form không bị vỡ layout, các ô input và nút bấm vừa vặn màn hình. | F15: 46175 | G15: Fail | H15: Form bị vỡ layout, nút bấm không hiển thị | I15: BUG1_ThanhToan | J15: La Thuận Phát
A16: TC05 | B16: Focus tự động vào ô báo lỗi | C16: 1. Cố tình bỏ trống form. 2. Bấm btn 'Đặt hàng'. | D16: Màn hình tự động cuộn lên và trỏ chuột focus vào ô bị lỗi đầu tiên. | F16: 46175 | G16: Pass | J16: La Thuận Phát
A17: TC06 | B17: Hiển thị placeholder/tooltip | C17: 1. Click vào từng ô input trên form. | D17: Hiển thị rõ text mờ hướng dẫn bên trong ô (VD: Nhập số điện thoại...). | F17: 46175 | G17: Pass | J17: La Thuận Phát
A18: TC07 | B18: Hiển thị text thông báo lỗi | C18: 1. Nhập sai định dạng các trường. 2. Bấm btn 'Đặt hàng'. | D18: Text báo lỗi xuất hiện bên dưới input, có màu đỏ để dễ nhận biết. | F18: 46175 | G18: Pass | J18: La Thuận Phát
A19: TC08 | B19: Điều hướng form bằng phím Tab | C19: 1. Trỏ chuột vào ô đầu tiên. 2. Bấm phím Tab liên tục. | D19: Con trỏ nhảy đúng thứ tự tuần tự từ trên xuống dưới, trái qua phải. | F19: 46175 | G19: Pass | J19: La Thuận Phát
A20: TC09 | B20: Font chữ và độ tương phản | C20: 1. Truy cập trang bằng nhiều thiết bị/màn hình. | D20: Chữ rõ nét, màu chữ và màu nền tương phản tốt, không bị chìm. | F20: 46175 | G20: Pass | J20: La Thuận Phát
A21: Form Validation
A22: TC10 | B22: Check validate bỏ trống form | C22: 1. Bỏ trống toàn bộ các field trong form. 2. Bấm btn 'Đặt hàng'. | D22: Hiển thị text báo lỗi dưới các field yêu cầu nhập đầy đủ thông tin. | F22: 46175 | G22: Pass | J22: La Thuận Phát
A23: TC11 | B23: Check validate SĐT chứa chữ cái | C23: 1. Nhập SĐT chứa ký tự chữ. 2. Bấm btn 'Đặt hàng'. | D23: Hiển thị text báo lỗi định dạng SĐT không hợp lệ. | F23: 46175 | G23: Fail | H23: Alert text : Đã thêm vào giỏ hàng! | I23: BUG2_ThanhToan | J23: La Thuận Phát
A24: TC12 | B24: Check validate SĐT sai độ dài | C24: 1. Nhập SĐT có 8 số. 2. Bấm btn 'Đặt hàng'. | D24: Hiển thị text báo lỗi SĐT phải có đủ 10 chữ số. | F24: 46175 | G24: Fail | H24: Không tìm thấy thông báo lỗi: 'SĐT phải có đủ 10 chữ số' trên màn hình hoặc trong validationMessage (Lỗi thực tế nhận được: '' | I24: BUG3_ThanhToan | J24: La Thuận Phát
A25: TC13 | B25: Check validate SĐT không bắt đầu bằng số 0 | C25: 1. Nhập SĐT bắt đầu bằng số khác 0. 2. Bấm btn 'Đặt hàng'. | D25: Hiển thị text báo lỗi SĐT phải bắt đầu bằng số 0. | F25: 46175 | G25: Fail | H25: Không tìm thấy thông báo lỗi: 'SĐT phải bắt đầu bằng số 0' trên màn hình hoặc trong validationMessage (Lỗi thực tế nhận được: '' | I25: BUG4_ThanhToan | J25: La Thuận Phát
A26: TC14 | B26: Check validate Email sai định dạng | C26: 1. Nhập email không có @. 2. Bấm btn 'Đặt hàng'. | D26: Hiển thị text báo lỗi định dạng Email không hợp lệ. | F26: 46175 | G26: Pass | J26: La Thuận Phát
A27: TC15 | B27: Check validate Email vượt quá độ dài | C27: 1. Nhập email dài hơn 255 ký tự. 2. Bấm btn 'Đặt hàng'. | D27: Hiển thị text báo lỗi email vượt quá số ký tự cho phép. | F27: 46175 | G27: Fail | H27: Alert text : Đã thêm vào giỏ hàng! | I27: BUG5_ThanhToan | J27: La Thuận Phát
A28: TC16 | B28: Check validate Email có tiếng Việt | C28: 1. Nhập email chứa ký tự tiếng Việt có dấu. 2. Bấm btn 'Đặt hàng'. | D28: Hiển thị text báo lỗi email không được chứa tiếng Việt có dấu. | F28: 46175 | G28: Pass | J28: La Thuận Phát
A29: TC17 | B29: Check validate Email nhiều ký tự @ | C29: 1. Nhập email chứa nhiều dấu @. 2. Bấm btn 'Đặt hàng'. | D29: Hiển thị text báo lỗi định dạng Email không hợp lệ. | F29: 46175 | G29: Pass | J29: La Thuận Phát
A30: TC18 | B30: Check validate nhập toàn space vào Tên | C30: 1. Nhập khoảng trắng vào field Tên. 2. Bấm btn 'Đặt hàng'. | D30: Hiển thị text báo lỗi không được để trống Họ Tên. | F30: 46175 | G30: Fail | H30: Alert text : Đã thêm vào giỏ hàng! | I30: BUG6_ThanhToan | J30: La Thuận Phát
A31: TC19 | B31: Check validate Họ tên vượt quá độ dài | C31: 1. Nhập tên dài hơn quy định (VD: 100 ký tự). 2. Bấm btn 'Đặt hàng'. | D31: Hiển thị text báo lỗi Họ Tên vượt quá giới hạn ký tự. | F31: 46175 | G31: Fail | H31: Alert text : Đã thêm vào giỏ hàng! | I31: BUG7_ThanhToan | J31: La Thuận Phát
A32: TC20 | B32: Check validate Họ tên có ký tự đặc biệt | C32: 1. Nhập tên chứa @, #, $. 2. Bấm btn 'Đặt hàng'. | D32: Hiển thị text báo lỗi Họ Tên không được chứa ký tự đặc biệt. | F32: 46175 | G32: Fail | H32: Alert text : Đã thêm vào giỏ hàng! | I32: BUG8_ThanhToan | J32: La Thuận Phát
A33: TC21 | B33: Check validate Địa chỉ vượt quá độ dài | C33: 1. Nhập chuỗi địa chỉ cực dài (> 500 ký tự). 2. Bấm btn 'Đặt hàng'. | D33: Hiển thị text báo lỗi Địa chỉ quá dài. | F33: 46175 | G33: Fail | H33: Không tìm thấy thông báo lỗi: 'Địa chỉ quá dài' trên màn hình hoặc trong validationMessage (Lỗi thực tế nhận được: '' | I33: BUG9_ThanhToan | J33: La Thuận Phát
A34: TC22 | B34: Check validate Địa chỉ toàn ký tự đặc biệt | C34: 1. Nhập các ký hiệu đặc biệt vào field Địa chỉ. 2. Bấm btn 'Đặt hàng'. | D34: Hiển thị text báo lỗi Địa chỉ không hợp lệ. | F34: 46175 | G34: Fail | H34: Không tìm thấy thông báo lỗi: 'Địa chỉ không hợp lệ' trên màn hình hoặc trong validationMessage (Lỗi thực tế nhận được: '' | I34: BUG10_ThanhToan | J34: La Thuận Phát
A35: TC23 | B35: Check validate SĐT chứa khoảng trắng | C35: 1. Nhập SĐT chứa khoảng trắng xen kẽ. 2. Bấm btn 'Đặt hàng'. | D35: Hệ thống tự loại bỏ khoảng trắng hoặc hiển thị lỗi yêu cầu nhập sát nhau. | F35: 46175 | G35: Fail | H35: Không tìm thấy thông báo lỗi: 'SĐT không hợp lệ' trên màn hình hoặc trong validationMessage (Lỗi thực tế nhận được: '' | I35: BUG11_ThanhToan | J35: La Thuận Phát
A36: TC24 | B36: Check validate Email thiếu domain | C36: 1. Nhập email kết thúc bằng ký tự '.' . 2. Bấm btn 'Đặt hàng'. | D36: Hiển thị text báo lỗi định dạng Email. | F36: 46175 | G36: Pass | J36: La Thuận Phát
A37: TC25 | B37: Nhập mã giảm giá không tồn tại | C37: 1. Nhập mã sai vào ô Voucher. 2. Bấm btn 'Áp dụng'. | D37: Hiển thị popup/text báo lỗi mã giảm giá không tồn tại. | F37: 46175 | G37: Fail | H37: Trang web không có Voucher. | I37: BUG12_ThanhToan | J37: La Thuận Phát
A38: TC26 | B38: Nhập mã giảm giá đã hết hạn | C38: 1. Nhập mã đã qua hạn dùng. 2. Bấm btn 'Áp dụng'. | D38: Hiển thị text báo lỗi mã giảm giá đã hết hạn hoặc hết lượt. | F38: 46175 | G38: Fail | H38: Trang web không có Voucher. | I38: BUG13_ThanhToan | J38: La Thuận Phát
A39: TC27 | B39: Để trống mã giảm giá và bấm Áp dụng | C39: 1. Để trống field mã giảm giá. 2. Bấm btn 'Áp dụng'. | D39: Hiển thị báo lỗi yêu cầu nhập mã giảm giá. | F39: 46175 | G39: Fail | H39: Trang web không có Voucher. | I39: BUG14_ThanhToan | J39: La Thuận Phát
A40: TC28 | B40: Nhập chữ vào input số lượng | C40: 1. Bôi đen số lượng, nhập chữ cái vào. 2. Click ra ngoài. | D40: Không cho nhập chữ, hệ thống tự động reset lại giá trị là 1. | F40: 46175 | G40: Fail | H40: Trang web không có Voucher. | I40: BUG15_ThanhToan | J40: La Thuận Phát
A41: Functional
A42: TC29 | B42: Đặt hàng COD thành công | C42: 1. Điền data đúng. 2. Chọn Thanh toán khi nhận hàng. 3. Bấm Đặt hàng. | D42: Chuyển hướng sang trang "Đặt hàng thành công", hiển thị mã đơn. | F42: 46175 | G42: Pass | J42: La Thuận Phát
A43: TC30 | B43: Xóa giỏ hàng sau thanh toán | C43: 1. Tạo đơn hàng thành công. 2. Quay về trang chủ, vào lại Giỏ hàng. | D43: Giỏ hàng báo trống (0 sản phẩm). | F43: 46175 | G43: Pass | J43: La Thuận Phát
...
